<?xml version="1.0"?>
<robot name="sixthwheelcombi">

  <material name="blue">
    <color rgba="0 0 0.8 1"/>
  </material>

  <material name="yellow">
    <color rgba="0.8 0.8 0 1"/>
  </material>

  <material name="red">
    <color rgba="0.6 0 0 1"/>
  </material>

  <material name="white">
    <color rgba="1 1 1 1"/>
  </material>


  <link name="semi">
    <visual>
      <geometry>
        <box size="1.0 2.0 1.0"/>
      </geometry>
      <material name="blue"/>
    </visual>
    <collision>
      <geometry>
        <box size="1.0 2.0 1.0"/>
      </geometry>
    </collision>
  </link>

  <joint name="hitch1" type="floating">
    <origin xyz="0 -2.1 0" rpy="0 0 0"/>
    <parent link="semi"/>
    <child link="sixthwheel"/>
  </joint>

  <link name="sixthwheel">
    <visual>
      <geometry>
        <box size="1.0 2.0 1.0"/>
      </geometry>
      <material name="yellow"/>
    </visual>
    <collision>
      <geometry>
        <box size="1.0 2.0 1.0"/>s
      </geometry>
    </collision>
  </link>

  <joint name="hitch2" type="floating">
    <origin xyz="0 -4.1 0" rpy="0 0 0"/>
    <parent link="sixthwheel"/>
    <child link="trailer"/>
  </joint>

  <link name="trailer">
    <visual>
      <geometry>
        <box size="1.0 5.0 1.0"/>
      </geometry>
      <material name="red"/>
    </visual>
    <collision>
      <geometry>
        <box size="1.0 5.0 1.0"/>s
      </geometry>
    </collision>
  </link>

</robot>